Workbook

Sheet Q2026-03 pedido MLTI
A1: ITEM | B1: ITEM ID. | C1: Standard | D1: DESCRIPTION ENGLISH | E1: MATERIAL | F1: SIZE(Thickness x Length) | G1: Unit | H1: 1st Shipment | I1: 2nd Shipment | J1: 3rd Shipment | K1: MLTI Price unit. USD | L1: MLTI Price Total USD | M1: NET WEIGHT (kg) | N1: 1st Shpt. Total N.W. (KG) | O1: 2nd Shpt. Total N.W. (KG) | P1: 3rd Total N.W. (KG) | Q1: NCM | R1: Heat Number
A2: 1 | B2: MSC2403.1103 | C2: A554 | D2: TUBE ROUND WELDED/ASTM A554 ORNAMENTAL STAINLESS/ OUTSIDE POLISHED 600 GRIT /THICKNESS 1.2MM X LENGTH 6000MM/PC | E2: 304 | F2: OD009,525 (3/8P) x 1,2MM x 6MTS | G2: METERS | H2: 990 | K2: 0.73 | L2: =(H2+I2+J2)*K2 -> 722.7 | M2: 0.2472525 | N2: =M2*H2 -> 244.77998 | Q2: 73064000
A3: 2 | B3: MSC2403.1104 | C3: A554 | D3: TUBE ROUND WELDED/ASTM A554 ORNAMENTAL STAINLESS/ OUTSIDE POLISHED 600 GRIT /THICKNESS 1.2MM X LENGTH 6000MM/PC | E3: 304 | F3: OD012,70 (1/2P) x 1,2MM x 6MTS | G3: METERS | H3: 738 | I3: 738 | J3: =I3*2 -> 1476 | K3: 0.89 | L3: =(H3+I3+J3)*K3 -> 2627.28 | M3: 0.34155 | N3: =M3*H3 -> 252.0639 | O3: =M3*I3 -> 252.0639 | P3: =M3*J3 -> 504.1278 | Q3: 73064000
A4: 3 | B4: MSC2403.1196 | C4: A554 | D4: TUBE ROUND WELDED/ASTM A554 ORNAMENTAL STAINLESS/ OUTSIDE POLISHED 600 GRIT /THICKNESS 1.2MM X LENGTH 6000MM/PC | E4: 304 | F4: OD015,875 (5/8P) x 1,2MM x 6MTS | G4: METERS | H4: 570 | K4: 1.14 | L4: =(H4+I4+J4)*K4 -> 649.8 | M4: 0.4358475 | N4: =M4*H4 -> 248.43308 | Q4: 73064000
A5: 4 | B5: MSC2403.1105 | C5: A554 | D5: TUBE ROUND WELDED/ASTM A554 ORNAMENTAL STAINLESS/ OUTSIDE POLISHED 600 GRIT /THICKNESS 1.2MM X LENGTH 6000MM/PC | E5: 304 | F5: OD019,05 (3/4P) x 1,2MM x 6MTS | G5: METERS | H5: 474 | I5: 474 | J5: =I5*2 -> 948 | K5: 1.36 | L5: =(H5+I5+J5)*K5 -> 2578.56 | M5: 0.530145 | N5: =M5*H5 -> 251.28873 | O5: =M5*I5 -> 251.28873 | P5: =M5*J5 -> 502.57746 | Q5: 73064000
A6: 5 | B6: MSC2403.1195 | C6: A554 | D6: TUBE ROUND WELDED/ASTM A554 ORNAMENTAL STAINLESS/ OUTSIDE POLISHED 600 GRIT /THICKNESS 1.2MM X LENGTH 6000MM/PC | E6: 304 | F6: OD022,225 (7/8P) x 1,2MM x 6MTS | G6: METERS | H6: 402 | K6: 1.6 | L6: =(H6+I6+J6)*K6 -> 643.2 | M6: 0.6244425 | N6: =M6*H6 -> 251.02589 | Q6: 73064000
A7: 6 | B7: MSC2403.1106 | C7: A554 | D7: TUBE ROUND WELDED/ASTM A554 ORNAMENTAL STAINLESS/ OUTSIDE POLISHED 600 GRIT /THICKNESS 1.2MM X LENGTH 6000MM/PC | E7: 304 | F7: OD025,40 (1P) x 1,2MM x 6MTS | G7: METERS | H7: 690 | I7: 1080 | J7: =I7*2 -> 2160 | K7: 1.84 | L7: =(H7+I7+J7)*K7 -> 7231.2 | M7: 0.71874 | N7: =M7*H7 -> 495.9306 | O7: =M7*I7 -> 776.2392 | P7: =M7*J7 -> 1552.4784 | Q7: 73064000
A8: 7 | B8: MSC2403.1107 | C8: A554 | D8: TUBE ROUND WELDED/ASTM A554 ORNAMENTAL STAINLESS/ OUTSIDE POLISHED 600 GRIT /THICKNESS 1.2MM X LENGTH 6000MM/PC | E8: 304 | F8: OD031,75 (1.1/4P) x 1,2MM x 6MTS | G8: METERS | H8: 276 | I8: 276 | J8: =I8*2 -> 552 | K8: 2.33 | L8: =(H8+I8+J8)*K8 -> 2572.32 | M8: 0.907335 | N8: =M8*H8 -> 250.42446 | O8: =M8*I8 -> 250.42446 | P8: =M8*J8 -> 500.84892 | Q8: 73064000
A9: 8 | B9: MSC2403.1108 | C9: A554 | D9: TUBE ROUND WELDED/ASTM A554 ORNAMENTAL STAINLESS/ OUTSIDE POLISHED 600 GRIT /THICKNESS 1.2MM X LENGTH 6000MM/PC | E9: 304 | F9: OD038,10 (1.1/2P) x 1,2MM x 6MTS | G9: METERS | H9: 1200 | I9: 1500 | J9: =I9*2 -> 3000 | K9: 2.81 | L9: =(H9+I9+J9)*K9 -> 16017 | M9: 1.09593 | N9: =M9*H9 -> 1315.116 | O9: =M9*I9 -> 1643.895 | P9: =M9*J9 -> 3287.79 | Q9: 73064000
A10: 9 | B10: MSC2403.1109 | C10: A554 | D10: TUBE ROUND WELDED/ASTM A554 ORNAMENTAL STAINLESS/ OUTSIDE POLISHED 600 GRIT /THICKNESS 1.2MM X LENGTH 6000MM/PC | E10: 304 | F10: OD050,80 (2P) x 1,2MM x 6MTS | G10: METERS | H10: 1200 | I10: 1500 | J10: =I10*2 -> 3000 | K10: 3.77 | L10: =(H10+I10+J10)*K10 -> 21489 | M10: 1.47312 | N10: =M10*H10 -> 1767.744 | O10: =M10*I10 -> 2209.68 | P10: =M10*J10 -> 4419.36 | Q10: 73064000
A11: 10 | B11: MSC2403.1203 | C11: A554 | D11: TUBE ROUND WELDED/ASTM A554 ORNAMENTAL STAINLESS/ OUTSIDE POLISHED 600 GRIT /THICKNESS 1.5MM X LENGTH 6000MM/PC | E11: 304 | F11: OD009,525 (3/8P) x 1,5MM x 6MTS | G11: METERS | H11: 810 | K11: 0.88 | L11: =(H11+I11+J11)*K11 -> 712.8 | M11: 0.29792813 | N11: =M11*H11 -> 241.32178 | Q11: 73064000
A12: 11 | B12: MSC2403.1204 | C12: A554 | D12: TUBE ROUND WELDED/ASTM A554 ORNAMENTAL STAINLESS/ OUTSIDE POLISHED 600 GRIT /THICKNESS 1.5MM X LENGTH 6000MM/PC | E12: 304 | F12: OD012,70 (1/2P) x 1,5MM x 6MTS | G12: METERS | H12: 1200 | I12: 1200 | J12: =I12*2 -> 2400 | K12: 1.06 | L12: =(H12+I12+J12)*K12 -> 5088 | M12: 0.4158 | N12: =M12*H12 -> 498.96 | O12: =M12*I12 -> 498.96 | P12: =M12*J12 -> 997.92 | Q12: 73064000
A13: 12 | B13: MSC2403.1296 | C13: A554 | D13: TUBE ROUND WELDED/ASTM A554 ORNAMENTAL STAINLESS/ OUTSIDE POLISHED 600 GRIT /THICKNESS 1.5MM X LENGTH 6000MM/PC | E13: 304 | F13: OD015,875 (5/8P) x 1,5MM x 6MTS | G13: METERS | H13: 468 | K13: 1.36 | L13: =(H13+I13+J13)*K13 -> 636.48 | M13: 0.53367188 | N13: =M13*H13 -> 249.75844 | Q13: 73064000
A14: 13 | B14: MSC2403.1205 | C14: A554 | D14: TUBE ROUND WELDED/ASTM A554 ORNAMENTAL STAINLESS/ OUTSIDE POLISHED 600 GRIT /THICKNESS 1.5MM X LENGTH 6000MM/PC | E14: 304 | F14: OD019,05 (3/4P) x 1,5MM x 6MTS | G14: METERS | H14: 1800 | I14: 1800 | J14: =I14*2 -> 3600 | K14: 1.63 | L14: =(H14+I14+J14)*K14 -> 11736 | M14: 0.65154375 | N14: =M14*H14 -> 1172.7788 | O14: =M14*I14 -> 1172.7788 | P14: =M14*J14 -> 2345.5575 | Q14: 73064000
A15: 14 | B15: MSC2403.1295 | C15: A554 | D15: TUBE ROUND WELDED/ASTM A554 ORNAMENTAL STAINLESS/ OUTSIDE POLISHED 600 GRIT /THICKNESS 1.5MM X LENGTH 6000MM/PC | E15: 304 | F15: OD022,225 (7/8P) x 1,5MM x 6MTS | G15: METERS | H15: 324 | K15: 1.93 | L15: =(H15+I15+J15)*K15 -> 625.32 | M15: 0.76941563 | N15: =M15*H15 -> 249.29066 | Q15: 73064000
A16: 15 | B16: MSC2403.1206 | C16: A554 | D16: TUBE ROUND WELDED/ASTM A554 ORNAMENTAL STAINLESS/ OUTSIDE POLISHED 600 GRIT /THICKNESS 1.5MM X LENGTH 6000MM/PC | E16: 304 | F16: OD025,40 (1P) x 1,5MM x 6MTS | G16: METERS | H16: 1200 | I16: 1500 | J16: =I16*2 -> 3000 | K16: 2.22 | L16: =(H16+I16+J16)*K16 -> 12654 | M16: 0.8872875 | N16: =M16*H16 -> 1064.745 | O16: =M16*I16 -> 1330.9312 | P16: =M16*J16 -> 2661.8625 | Q16: 73064000
A17: 16 | B17: MSC2403.1207 | C17: A554 | D17: TUBE ROUND WELDED/ASTM A554 ORNAMENTAL STAINLESS/ OUTSIDE POLISHED 600 GRIT /THICKNESS 1.5MM X LENGTH 6000MM/PC | E17: 304 | F17: OD031,75 (1.1/4P) x 1,5MM x 6MTS | G17: METERS | H17: 450 | I17: 450 | J17: =I17*2 -> 900 | K17: 2.81 | L17: =(H17+I17+J17)*K17 -> 5058 | M17: 1.1230313 | N17: =M17*H17 -> 505.36406 | O17: =M17*I17 -> 505.36406 | P17: =M17*J17 -> 1010.7281 | Q17: 73064000
A18: 17 | B18: MSC2403.1208 | C18: A554 | D18: TUBE ROUND WELDED/ASTM A554 ORNAMENTAL STAINLESS/ OUTSIDE POLISHED 600 GRIT /THICKNESS 1.5MM X LENGTH 6000MM/PC | E18: 304 | F18: OD038,10 (1.1/2P) x 1,5MM x 6MTS | G18: METERS | H18: 2400 | I18: 2700 | J18: =I18*2 -> 5400 | K18: 3.4 | L18: =(H18+I18+J18)*K18 -> 35700 | M18: 1.358775 | N18: =M18*H18 -> 3261.06 | O18: =M18*I18 -> 3668.6925 | P18: =M18*J18 -> 7337.385 | Q18: 73064000
A19: 18 | B19: MSC2403.1209 | C19: A554 | D19: TUBE ROUND WELDED/ASTM A554 ORNAMENTAL STAINLESS/ OUTSIDE POLISHED 600 GRIT /THICKNESS 1.5MM X LENGTH 6000MM/PC | E19: 304 | F19: OD050,80 (2P) x 1,5MM x 6MTS | G19: METERS | H19: 3300 | I19: 3780 | J19: =I19*2 -> 7560 | K19: 4.57 | L19: =(H19+I19+J19)*K19 -> 66904.8 | M19: 1.8302625 | N19: =M19*H19 -> 6039.8663 | O19: =M19*I19 -> 6918.3922 | P19: =M19*J19 -> 13836.784 | Q19: 73064000
A20: 19 | B20: MSC2403.1210 | C20: A554 | D20: TUBE ROUND WELDED/ASTM A554 ORNAMENTAL STAINLESS/ OUTSIDE POLISHED 600 GRIT /THICKNESS 1.5MM X LENGTH 6000MM/PC | E20: 304 | F20: OD063,50 (2.1/2P) x 1,5MM x 6MTS | G20: METERS | H20: 216 | I20: 216 | J20: =I20*2 -> 432 | K20: 5.74 | L20: =(H20+I20+J20)*K20 -> 4959.36 | M20: 2.30175 | N20: =M20*H20 -> 497.178 | O20: =M20*I20 -> 497.178 | P20: =M20*J20 -> 994.356 | Q20: 73064000
A21: 20 | B21: MSC2403.1211 | C21: A554 | D21: TUBE ROUND WELDED/ASTM A554 ORNAMENTAL STAINLESS/ OUTSIDE POLISHED 600 GRIT /THICKNESS 1.5MM X LENGTH 6000MM/PC | E21: 304 | F21: OD076,20 (3P) x 1,5MM x 6MTS | G21: METERS | H21: 1040 | I21: 1200 | J21: =I21*2 -> 2400 | K21: 6.92 | L21: =(H21+I21+J21)*K21 -> 32108.8 | M21: 2.7732375 | N21: =M21*H21 -> 2884.167 | O21: =M21*I21 -> 3327.885 | P21: =M21*J21 -> 6655.77 | Q21: 73064000
A22: 21 | B22: MSC2403.1212 | C22: A554 | D22: TUBE ROUND WELDED/ASTM A554 ORNAMENTAL STAINLESS/ OUTSIDE POLISHED 600 GRIT /THICKNESS 1.5MM X LENGTH 6000MM/PC | E22: 304 | F22: OD101,60 (4P) x 1,5MM x 6MTS | G22: METERS | H22: 600 | I22: 900 | J22: =I22*2 -> 1800 | K22: 9.27 | L22: =(H22+I22+J22)*K22 -> 30591 | M22: 3.7162125 | N22: =M22*H22 -> 2229.7275 | O22: =M22*I22 -> 3344.5912 | P22: =M22*J22 -> 6689.1825 | Q22: 73064000
A23: 22 | B23: MSC2403.1413 | C23: A554 | D23: TUBE ROUND WELDED/ASTM A554 ORNAMENTAL STAINLESS/ OUTSIDE POLISHED 600 GRIT /THICKNESS 2.00MM X LENGTH 6000MM/PC | E23: 304 | F23: OD127,00 (5P) x 2,0MM | G23: METERS | H23: 120 | K23: 18.19 | L23: =(H23+I23+J23)*K23 -> 2182.8 | M23: 6.187 | N23: =M23*H23 -> 742.44 | Q23: 73064000
A24: 23 | B24: MSC2403.1414 | C24: A554 | D24: TUBE ROUND WELDED/ASTM A554 ORNAMENTAL STAINLESS/ OUTSIDE POLISHED 600 GRIT /THICKNESS 2.00MM X LENGTH 6000MM/PC | E24: 304 | F24: OD152,40 (6P) x 2,0MM | G24: METERS | H24: 120 | K24: 21.89 | L24: =(H24+I24+J24)*K24 -> 2626.8 | M24: 7.444 | N24: =M24*H24 -> 893.28 | Q24: 73064000
A25: 24 | B25: MSC2403.1415 | C25: A554 | D25: TUBE ROUND WELDED/ASTM A554 ORNAMENTAL STAINLESS/ OUTSIDE POLISHED 600 GRIT /THICKNESS 2.00MM X LENGTH 6000MM/PC | E25: 304 | F25: OD203,20 (8P) x 2,0MM | G25: METERS | H25: 120 | K25: 29.28 | L25: =(H25+I25+J25)*K25 -> 3513.6 | M25: 9.9594 | N25: =M25*H25 -> 1195.128 | Q25: 73064000
L26: =SUM(L2:L25) -> 269628.82 | N26: =SUM(N2:N25) -> 26801.872 | O26: =SUM(O2:O25) -> 26648.364 | P26: =SUM(P2:P25) -> 53296.729
B28: Prazo de entrega; 8 a 12 semanas
B29: Prazo de pagamento; 20/80
B30: Programação de pedido;
B31: Entrega 1(1cntr); Imediato todos os itens acima.
B32: Entrega 2(1cntr); Carregar 60dias após a saida da data do BL do carregamento anterior, e excluir os itens vermelho acima, e aumentar as quantidades dos itens azul proporcional, total 27toneladas.
B33: Entrega 3(2cntr); Carregar 60dias após a saida da data do BL do carregamento anterior, e excluir os itens vermelho acima, e aumentar as quantidades dos itens azul proporcional. Total 27toneladas
B35: abaixo incluir pedido de 1cntr - astm a270 incluir - imediato e 60dias após o carregamento mais 1cntr, total de 2cntrs.
A37: ITEM | B37: ITEM ID. | C37: Standard | D37: DESCRIPTION ENGLISH | E37: MATERIAL | F37: SIZE(Thickness x Length) | G37: Unit | H37: 1st Shipment | J37: MLTI Price unit. USD | K37: MLTI Price Total USD | L37: NET WEIGHT (kg) | M37: 1st Shpt. Total N.W. (KG) | O37: NCM | P37: Heat Number
A38: 1 | B38: MSC2401.1205 | C38: A270 | D38: TUBE ROUND WELDED ANNEALING/ASTM A270 SANITARY STAINLESS/SURFACE FINISH POLISHED OUTSIDE600 GRIT, INSIDE400 GRIT(Ra＜0.8μm) WITH MIRROR OUTSIDE | E38: 304 | F38: OD019,05 (3/4P) x 1,5MMx 6METERS | G38: METERS | H38: 210 | J38: =_xlfn.XLOOKUP(B38,[1]cotação!B:B,[1]cotação!S:S,0,0,1) -> 2.39 | K38: =(H38+I38)*J38 -> 501.9 | L38: 0.65154375 | M38: =H38*L38 -> 136.82419 | O38: 73064000
A39: 2 | B39: MSC2401.1206 | C39: A270 | D39: TUBE ROUND WELDED ANNEALING/ASTM A270 SANITARY STAINLESS/SURFACE FINISH POLISHED OUTSIDE600 GRIT, INSIDE400 GRIT(Ra＜0.8μm) WITH MIRROR OUTSIDE | E39: 304 | F39: OD025,40 (1P) x 1,5MMx 6METERS | G39: METERS | H39: 1500 | J39: =_xlfn.XLOOKUP(B39,[1]cotação!B:B,[1]cotação!S:S,0,0,1) -> 3.25 | K39: =(H39+I39)*J39 -> 4875 | L39: 0.8872875 | M39: =H39*L39 -> 1330.9312 | O39: 73064000
A40: 3 | B40: MSC2401.1207 | C40: A270 | D40: TUBE ROUND WELDED ANNEALING/ASTM A270 SANITARY STAINLESS/SURFACE FINISH POLISHED OUTSIDE600 GRIT, INSIDE400 GRIT(Ra＜0.8μm) WITH MIRROR OUTSIDE | E40: 304 | F40: OD031,75 (1.1/4P) x 1,5MMx 6METERS | G40: METERS | H40: 270 | J40: =_xlfn.XLOOKUP(B40,[1]cotação!B:B,[1]cotação!S:S,0,0,1) -> 4.12 | K40: =(H40+I40)*J40 -> 1112.4 | L40: 1.1230313 | M40: =H40*L40 -> 303.21844 | O40: 73064000
A41: 4 | B41: MSC2401.1208 | C41: A270 | D41: TUBE ROUND WELDED ANNEALING/ASTM A270 SANITARY STAINLESS/SURFACE FINISH POLISHED OUTSIDE600 GRIT, INSIDE400 GRIT(Ra＜0.8μm) WITH MIRROR OUTSIDE | E41: 304 | F41: OD038,10 (1.1/2P) x 1,5MMx 6METERS | G41: METERS | H41: 1860 | J41: =_xlfn.XLOOKUP(B41,[1]cotação!B:B,[1]cotação!S:S,0,0,1) -> 4.98 | K41: =(H41+I41)*J41 -> 9262.8 | L41: 1.358775 | M41: =H41*L41 -> 2527.3215 | O41: 73064000
A42: 5 | B42: MSC2401.1209 | C42: A270 | D42: TUBE ROUND WELDED ANNEALING/ASTM A270 SANITARY STAINLESS/SURFACE FINISH POLISHED OUTSIDE600 GRIT, INSIDE400 GRIT(Ra＜0.8μm) WITH MIRROR OUTSIDE | E42: 304 | F42: OD050,80 (2P) x 1,5MMx 6METERS | G42: METERS | H42: 4800 | J42: =_xlfn.XLOOKUP(B42,[1]cotação!B:B,[1]cotação!S:S,0,0,1) -> 6.71 | K42: =(H42+I42)*J42 -> 32208 | L42: 1.8302625 | M42: =H42*L42 -> 8785.26 | O42: 73064000
A43: 6 | B43: MSC2401.1210 | C43: A270 | D43: TUBE ROUND WELDED ANNEALING/ASTM A270 SANITARY STAINLESS/SURFACE FINISH POLISHED OUTSIDE600 GRIT, INSIDE400 GRIT(Ra＜0.8μm) WITH MIRROR OUTSIDE | E43: 304 | F43: OD063,50 (2.1/2P) x 1,5MMx 6METERS | G43: METERS | H43: 210 | J43: =_xlfn.XLOOKUP(B43,[1]cotação!B:B,[1]cotação!S:S,0,0,1) -> 8.44 | K43: =(H43+I43)*J43 -> 1772.4 | L43: 2.30175 | M43: =H43*L43 -> 483.3675 | O43: 73064000
...
